package com.dev.exception;

public class ExceptionHandling {

	public static void main(String[] args) throws CustomException {
		try {
			s();
			System.out.println("No Exception for s()");
			int res = divide (10,0);
			System.out.println("No exception for divide()");
			System.out.println(res);
		}
		catch(NegativeArraySizeException e) {
			System.out.println("Exception caught in catch block");
			System.out.println("getMessage(): "+e.getMessage());
			e.printStackTrace();
		}catch (ArithmeticException e) {
			System.err.println("Exception caught in catch block");
			System.err.println("getMessage(): +e.getMessage()");

		}finally {
			System.out.println("Finally Block");
			System.out.println("getMessage(): +e.getMessage()");
		}
		
		private static int divide(int i,int j) {
			return 0;
		}
			
			
			
			
			
			
			
			
			
			
			
			
			
			
			
			
			
			
			
			
			
		}
	
		

	}

}
